aocc/1.3.0(13):ERROR:150: Module 'aocc/1.3.0' conflicts with the currently loaded module(s) 'aocc/4.0.0'
aocc/1.3.0(13):ERROR:102: Tcl command execution failed:   conflict aocc

aocc/1.3.0(13):ERROR:150: Module 'aocc/1.3.0' conflicts with the currently loaded module(s) 'aocc/4.0.0'
aocc/1.3.0(13):ERROR:102: Tcl command execution failed:   conflict aocc

Building DAG of jobs...
Using shell: /usr/bin/bash
Provided cores: 8
Rules claiming more threads will be scaled down.
Provided resources: mem_mb=1000, mem_mib=954, disk_mb=1000, disk_mib=954
Select jobs to execute...

[Wed Dec 27 12:47:12 2023]
rule GatherLineages:
    input: /home/aglucaci/AOC-REM2/results/mammalian_REM2, /home/aglucaci/AOC-REM2/data/mammalian_REM2/Rem2_orthologs.csv, /home/aglucaci/AOC-REM2/results/mammalian_REM2/mammalian_REM2_codons.SA.FilterOutliers.fasta.treefile
    output: /home/aglucaci/AOC-REM2/results/mammalian_REM2/mammalian_REM2_codons.SA.FilterOutliers.fasta.treefile.log
    jobid: 8
    reason: Updated input files: /home/aglucaci/AOC-REM2/results/mammalian_REM2
    resources: mem_mb=1000, mem_mib=954, disk_mb=1000, disk_mib=954, tmpdir=/tmp

Traceback (most recent call last):
  File "/home/aglucaci/AOC-REM2/scripts/LineageAnnotation_Pipeline.py", line 83, in main
    handle = Entrez.esummary(db="nucleotide", id=ACCESSION, rettype="gb", retmode="text", retmax=1)
  File "/home/aglucaci/anaconda3/envs/AOC_REM2/lib/python3.10/site-packages/Bio/Entrez/__init__.py", line 342, in esummary
    return _open(cgi, variables)
  File "/home/aglucaci/anaconda3/envs/AOC_REM2/lib/python3.10/site-packages/Bio/Entrez/__init__.py", line 606, in _open
    handle = urlopen(cgi)
  File "/home/aglucaci/anaconda3/envs/AOC_REM2/lib/python3.10/urllib/request.py", line 216, in urlopen
    return opener.open(url, data, timeout)
  File "/home/aglucaci/anaconda3/envs/AOC_REM2/lib/python3.10/urllib/request.py", line 525, in open
    response = meth(req, response)
  File "/home/aglucaci/anaconda3/envs/AOC_REM2/lib/python3.10/urllib/request.py", line 634, in http_response
    response = self.parent.error(
  File "/home/aglucaci/anaconda3/envs/AOC_REM2/lib/python3.10/urllib/request.py", line 563, in error
    return self._call_chain(*args)
  File "/home/aglucaci/anaconda3/envs/AOC_REM2/lib/python3.10/urllib/request.py", line 496, in _call_chain
    result = func(*args)
  File "/home/aglucaci/anaconda3/envs/AOC_REM2/lib/python3.10/urllib/request.py", line 643, in http_error_default
    raise HTTPError(req.full_url, code, msg, hdrs, fp)
urllib.error.HTTPError: HTTP Error 429: Too Many Requests

During handling of the above exception, another exception occurred:

Traceback (most recent call last):
  File "/home/aglucaci/AOC-REM2/scripts/LineageAnnotation_Pipeline.py", line 132, in <module>
    main(transcript_accessions, DATA_DICT, TREE_NEWICK)
  File "/home/aglucaci/AOC-REM2/scripts/LineageAnnotation_Pipeline.py", line 88, in main
    handle = Entrez.esummary(db="nucleotide", id=ACCESSION, rettype="gb", retmode="text", retmax=1)
  File "/home/aglucaci/anaconda3/envs/AOC_REM2/lib/python3.10/site-packages/Bio/Entrez/__init__.py", line 342, in esummary
    return _open(cgi, variables)
  File "/home/aglucaci/anaconda3/envs/AOC_REM2/lib/python3.10/site-packages/Bio/Entrez/__init__.py", line 606, in _open
    handle = urlopen(cgi)
  File "/home/aglucaci/anaconda3/envs/AOC_REM2/lib/python3.10/urllib/request.py", line 216, in urlopen
    return opener.open(url, data, timeout)
  File "/home/aglucaci/anaconda3/envs/AOC_REM2/lib/python3.10/urllib/request.py", line 525, in open
    response = meth(req, response)
  File "/home/aglucaci/anaconda3/envs/AOC_REM2/lib/python3.10/urllib/request.py", line 634, in http_response
    response = self.parent.error(
  File "/home/aglucaci/anaconda3/envs/AOC_REM2/lib/python3.10/urllib/request.py", line 563, in error
    return self._call_chain(*args)
  File "/home/aglucaci/anaconda3/envs/AOC_REM2/lib/python3.10/urllib/request.py", line 496, in _call_chain
    result = func(*args)
  File "/home/aglucaci/anaconda3/envs/AOC_REM2/lib/python3.10/urllib/request.py", line 643, in http_error_default
    raise HTTPError(req.full_url, code, msg, hdrs, fp)
urllib.error.HTTPError: HTTP Error 429: Too Many Requests
[Wed Dec 27 12:47:46 2023]
Error in rule GatherLineages:
    jobid: 8
    input: /home/aglucaci/AOC-REM2/results/mammalian_REM2, /home/aglucaci/AOC-REM2/data/mammalian_REM2/Rem2_orthologs.csv, /home/aglucaci/AOC-REM2/results/mammalian_REM2/mammalian_REM2_codons.SA.FilterOutliers.fasta.treefile
    output: /home/aglucaci/AOC-REM2/results/mammalian_REM2/mammalian_REM2_codons.SA.FilterOutliers.fasta.treefile.log
    shell:
        python scripts/LineageAnnotation_Pipeline.py /home/aglucaci/AOC-REM2/results/mammalian_REM2 /home/aglucaci/AOC-REM2/data/mammalian_REM2/Rem2_orthologs.csv /home/aglucaci/AOC-REM2/results/mammalian_REM2/mammalian_REM2_codons.SA.FilterOutliers.fasta.treefile
        (one of the commands exited with non-zero exit code; note that snakemake uses bash strict mode!)

Shutting down, this might take some time.
Exiting because a job execution failed. Look above for error message
